Workbook

Sheet Дашборд
A1: Сводка по бу-запчастям Kia Rio 2019 1.4 Comfort
A2: Считается автоматически с листа «Прайс». Цены — диапазоны объявлений 2025–2026 гг., вся Россия.
A3: Позиций в таблице | C3: Категорий | E3: Позиций с ценой
A4: COUNTA('Прайс'!$C$4:$C$87) | C4: COUNTA('Дашборд'!$B$9:$B$15) | E4: COUNT('Прайс'!$E$4:$E$87)
A8: По категориям
A9: Категория | B9: Позиций | C9: Ср. мин, руб | D9: Ср. макс, руб | E9: Ср. цена, руб | F9: Диапазон
A10: Двигатель | B10: =COUNTIF('Прайс'!$B$4:$B$87,A10) | C10: =AVERAGEIF('Прайс'!$B$4:$B$87,A10,'Прайс'!$E$4:$E$87) | D10: =AVERAGEIF('Прайс'!$B$4:$B$87,A10,'Прайс'!$F$4:$F$87) | E10: =ROUND((C10+D10)/2,0) | F10: =D10-C10
A11: Трансмиссия и привод | B11: =COUNTIF('Прайс'!$B$4:$B$87,A11) | C11: =AVERAGEIF('Прайс'!$B$4:$B$87,A11,'Прайс'!$E$4:$E$87) | D11: =AVERAGEIF('Прайс'!$B$4:$B$87,A11,'Прайс'!$F$4:$F$87) | E11: =ROUND((C11+D11)/2,0) | F11: =D11-C11
A12: Подвеска и рулевое | B12: =COUNTIF('Прайс'!$B$4:$B$87,A12) | C12: =AVERAGEIF('Прайс'!$B$4:$B$87,A12,'Прайс'!$E$4:$E$87) | D12: =AVERAGEIF('Прайс'!$B$4:$B$87,A12,'Прайс'!$F$4:$F$87) | E12: =ROUND((C12+D12)/2,0) | F12: =D12-C12
A13: Тормоза | B13: =COUNTIF('Прайс'!$B$4:$B$87,A13) | C13: =AVERAGEIF('Прайс'!$B$4:$B$87,A13,'Прайс'!$E$4:$E$87) | D13: =AVERAGEIF('Прайс'!$B$4:$B$87,A13,'Прайс'!$F$4:$F$87) | E13: =ROUND((C13+D13)/2,0) | F13: =D13-C13
A14: Кузов и оптика | B14: =COUNTIF('Прайс'!$B$4:$B$87,A14) | C14: =AVERAGEIF('Прайс'!$B$4:$B$87,A14,'Прайс'!$E$4:$E$87) | D14: =AVERAGEIF('Прайс'!$B$4:$B$87,A14,'Прайс'!$F$4:$F$87) | E14: =ROUND((C14+D14)/2,0) | F14: =D14-C14
A15: Электрика | B15: =COUNTIF('Прайс'!$B$4:$B$87,A15) | C15: =AVERAGEIF('Прайс'!$B$4:$B$87,A15,'Прайс'!$E$4:$E$87) | D15: =AVERAGEIF('Прайс'!$B$4:$B$87,A15,'Прайс'!$F$4:$F$87) | E15: =ROUND((C15+D15)/2,0) | F15: =D15-C15
A16: Салон | B16: =COUNTIF('Прайс'!$B$4:$B$87,A16) | C16: =AVERAGEIF('Прайс'!$B$4:$B$87,A16,'Прайс'!$E$4:$E$87) | D16: =AVERAGEIF('Прайс'!$B$4:$B$87,A16,'Прайс'!$F$4:$F$87) | E16: =ROUND((C16+D16)/2,0) | F16: =D16-C16
A18: Как читать таблицу
A19: • Цены — диапазон реальных предложений б/у по всей России; итог зависит от состояния, региона и пробега донора.
A20: • «—» в колонке цены: публичные объявления с ценой не найдены — цена уточняется у конкретной разборки по телефону.
A21: • Kia Rio 2019 1.4 Comfort: двигатель G4LC (цепь ГРМ, ЭУР вместо ГУР, передний привод — заднего редуктора нет).
A22: • Данные: Avito, Дром (baza.drom.ru), агрегатор предложений разборок XBaz — сентябрь 2026.

Sheet Прайс
A1: БУ-запчасти Kia Rio 2019 1.4 Comfort (4-е поколение, G4LC 100 л.с.)
A2: Актуальные цены российского рынка (Avito, Дром, XBaz-агрегатор разборок), сентябрь 2026. БУ = б/у, контрактные, снятые с авто. «—» — цена публично не подтверждена, уточнять у разборок.
A3: № | B3: Категория | C3: Деталь | D3: Артикул / ориентир | E3: Цена мин, руб | F3: Цена макс, руб | G3: Ср. цена, руб | H3: Примечание
A4: 1 | B4: Двигатель | C4: Двигатель в сборе (контрактный G4LC 1.4) | D4: G4LC | E4: 89000 | F4: 135000 | G4: =ROUND((E4+F4)/2,0) | H4: Б/у контрактные 89–99 тыс.; новые контрактные до 120–135 тыс. (XBaz, Дром)
A5: 2 | B5: Двигатель | C5: ГБЦ в сборе (головка блока) | D5: G4LC/G4LA | E5: 30900 | F5: 30900 | G5: =ROUND((E5+F5)/2,0) | H5: В сборе, Recyрс Москва (Дром)
A6: 3 | B6: Двигатель | C6: Блок цилиндров | D6: 2110003940 | E6: 9000 | F6: 25700 | G6: =ROUND((E6+F6)/2,0) | H6: Rio 4 2019 ~15 тыс. (Ярославль); перебор 9–25,7 тыс. (Дром)
A7: 4 | B7: Двигатель | C7: Поддон двигателя | D7: 2113503920 | E7: 8000 | F7: 16200 | G7: =ROUND((E7+F7)/2,0) | H7: Полуподдон 8–10 тыс.; поддон 13,6–16,2 тыс. (Дром)
A8: 5 | B8: Двигатель | C8: Клапанная крышка | D8: G4LC | E8: 5500 | F8: 5500 | G8: =ROUND((E8+F8)/2,0) | H8: Оригинал б/у (Avito)
A9: 6 | B9: Двигатель | C9: Форсунки (1 шт / комплект) | D9: 1.4 G4LC | E9: — | F9: — | G9: — | H9: Бу-цены не публикуются, по запросу разборок
A10: 7 | B10: Двигатель | C10: Топливный насос (модуль в баке) | D10: 311104L000 | E10: — | F10: — | G10: — | H10: Цены по запросу разборок
A11: 8 | B11: Двигатель | C11: Датчик расхода воздуха (MAF) | D11: 1.6 G4FG совм. | E11: 1000 | F11: 1500 | G11: =ROUND((E11+F11)/2,0) | H11: Для 1.4 G4LC уточнять (Avito)
A12: 9 | B12: Двигатель | C12: Датчики (коленвала/детонации/темп.) | D12: 1.4 | E12: 270 | F12: 2500 | G12: =ROUND((E12+F12)/2,0) | H12: Детонация 270 ₽; коленвал 1,8–2,5 тыс. (Avito, Inycar)
A13: 10 | B13: Двигатель | C13: Дроссельная заслонка | D13: G4LC | E13: — | F13: — | G13: — | H13: Цены по запросу разборок
A14: 11 | B14: Двигатель | C14: Впускной коллектор (ресивер) | D14: G4LC | E14: — | F14: — | G14: — | H14: Цены по запросу разборок
A15: 12 | B15: Двигатель | C15: Водяной насос (помпа) | D15: 1.4 | E15: — | F15: — | G15: — | H15: Как правило меняется на новый
A16: 13 | B16: Двигатель | C16: Термостат в сборе | D16: 1.4 | E16: — | F16: — | G16: — | H16: Как правило меняется на новый
A17: 14 | B17: Двигатель | C17: Радиатор охлаждения | D17: 25310H5000 | E17: 3500 | F17: 3500 | G17: =ROUND((E17+F17)/2,0) | H17: Частные объявления (Avito)
A18: 15 | B18: Двигатель | C18: Вентилятор охлаждения (с кожухом) | D18: 1.4 | E18: — | F18: — | G18: — | H18: Цены по запросу разборок
A19: 16 | B19: Двигатель | C19: Патрубки/шланги охлаждения | D19: 1.4 | E19: — | F19: — | G19: — | H19: Обычно новые
A20: 17 | B20: Двигатель | C20: Катушка зажигания (1 шт) | D20: 2730103200 | E20: 1800 | F20: 2500 | G20: =ROUND((E20+F20)/2,0) | H20: Ориентир контракт/новые; бу уточнять (Avito)
A21: 18 | B21: Двигатель | C21: Цепь ГРМ (комплект) | D21: G4LC | E21: — | F21: — | G21: — | H21: Привод цепной; бу почти не встречается, меняется на новый
A22: 19 | B22: Двигатель | C22: Генератор (бу/восстановленный) | D22: 37300-03870 | E22: — | F22: — | G22: — | H22: Много предложений, цены по запросу (Avito)
A23: 20 | B23: Двигатель | C23: Стартер (бу/восстановленный) | D23: 36100-03853 | E23: — | F23: — | G23: — | H23: Контрактные в наличии, цена по запросу
A24: 21 | B24: Двигатель | C24: Компрессор кондиционера | D24: 97701H5000 | E24: — | F24: — | G24: — | H24: В рублях не подтверждена, уточнять
A25: 22 | B25: Двигатель | C25: Катализатор (снятый небитый) | D25: 1.4/1.6 | E25: 7500 | F25: 7500 | G25: =ROUND((E25+F25)/2,0) | H25: Avito (с Рио 1.6, 170 тыс. км)
A26: 23 | B26: Двигатель | C26: Выпускной коллектор (с катализатором) | D26: G4LC | E26: — | F26: — | G26: — | H26: Цены по запросу разборок
A27: 24 | B27: Двигатель | C27: Резонатор / глушитель в сборе | D27: 28600H5100 | E27: 3800 | F27: 15000 | G27: =ROUND((E27+F27)/2,0) | H27: 1.4 G4LC 4,1–9 тыс.; до 15 тыс. (Дром)
A28: 25 | B28: Двигатель | C28: Масляный насос | D28: 2131003800 | E28: 8000 | F28: 12000 | G28: =ROUND((E28+F28)/2,0) | H28: Оригинал; бу-цена не подтверждена (клуб)
A29: 26 | B29: Двигатель | C29: Радиатор отопителя (печки) | D29: 1.4 | E29: 3000 | F29: 5310 | G29: =ROUND((E29+F29)/2,0) | H29: Новый аналог 5 310 ₽; бу дешевле (Avito)
A30: 27 | B30: Двигатель | C30: Моторчик отопителя (печки) | D30: 1.4 | E30: 2222 | F30: 5600 | G30: =ROUND((E30+F30)/2,0) | H30: Моторчик 2 222 ₽; корпус печки 5–5,6 тыс. (Avito)
A31: 28 | B31: Двигатель | C31: Выпускной коллектор | D31: G4LC | E31: — | F31: — | G31: — | H31: Уточнять у разборок
A32: 29 | B32: Трансмиссия и привод | C32: АКПП 6-ст (A6GF1, контракт) | D32: A6GF1 | E32: 80000 | F32: 110000 | G32: =ROUND((E32+F32)/2,0) | H32: Rio 4 2019 1.4 — 99,9–100 тыс. (XBaz, Дром)
A33: 30 | B33: Трансмиссия и привод | C33: МКПП 6-ст (б/у) | D33: M6CF1 | E33: 50000 | F33: 50000 | G33: =ROUND((E33+F33)/2,0) | H33: Avito (2017–2022, 1.4 G4LC)
A34: 31 | B34: Трансмиссия и привод | C34: Сцепление (комплект, б/у) | D34: 1.4 | E34: 3900 | F34: 9465 | G34: =ROUND((E34+F34)/2,0) | H34: Бу 3,9 тыс. (справочно 1.4); новый аналог 9,5 тыс.
A35: 32 | B35: Трансмиссия и привод | C35: Полуоси (приводы) | D35: 49500H0300 | E35: — | F35: — | G35: — | H35: Цены по запросу; новые от ~9,2 тыс.
A36: 33 | B36: Трансмиссия и привод | C36: ШРУС | D36: 1.4 | E36: — | F36: — | G36: — | H36: Цены по запросу разборок
A37: 34 | B37: Трансмиссия и привод | C37: Редуктор заднего моста | E37: — | F37: — | G37: — | H37: Не применимо — передний привод
A38: 35 | B38: Подвеска и рулевое | C38: Рычаг передний нижний | D38: 54500H5000 | E38: — | F38: — | G38: — | H38: Оригинал б/у есть, цена по запросу
A39: 36 | B39: Подвеска и рулевое | C39: Сайлентблоки / шаровые | D39: 54584H5000 | E39: — | F39: — | G39: — | H39: Бу рынок не распространён — обычно новые
A40: 37 | B40: Подвеска и рулевое | C40: Амортизатор передний | D40: 1.4 | E40: 1500 | F40: 4000 | G40: =ROUND((E40+F40)/2,0) | H40: Бу от 1,5 тыс. (Avito); контракт до 4 тыс.
...

Sheet Источники
A1: Источники и площадки поиска
A2: Цены собраны из публичных объявлений и каталогов разборок 2025–2026 гг.
A3: Площадка | B3: Что искать | C3: Тип | D3: Примечание
A4: Avito | B4: Любые бу-запчасти Rio 4 | C4: Доска объявлений | D4: Основной источник наличия; часть цен скрыта в объявлениях
A5: Дром / baza.drom.ru | B5: Двигатель, ГБЦ, суппорта, ЭУР, блок ABS, резонатор | C5: База объявлений | D5: Конкретные цены от разборок, вся Россия
A6: XBaz (xbaz.ru) | B6: Кузов, оптика, электрика, салон, ECU | C6: Агрегатор разборок | D6: Сводит предложения Kar Market, SPART, ZapMap, Прогресс и др.
A7: Фарпост (farpost.ru) | B7: Блок ABS, электроника | C7: Доска объявлений | D7: Контрактные запчасти
A8: X-BAZ — каталог Rio 4 | B8: Все категории | C8: Агрегатор | D8: ak-riq 4 поколение 2016–2026
A9: Магазины (Inycar, sloboda-avto, rioclub) | B9: Датчики, стартер, масляный насос | C9: Магазин/клуб | D9: Ориентир цен, в т.ч. новые аналоги
