Workbook

Sheet Дашборд
A1: Сводка по бу-запчастям Lada Vesta 2018
A2: Считается автоматически с листа «Прайс». Сентябрь 2026, вся Россия.
A3: Позиций в таблице | C3: Категорий | E3: Позиций с ценой
A4: =COUNTA('Прайс'!$C$4:$C$47) -> 44 | C4: =COUNTA('Дашборд'!$B$9:$B$15) -> 7 | E4: =COUNT('Прайс'!$E$4:$E$47) -> 17
A8: По категориям
A9: Категория | B9: Позиций | C9: Ср. мин, руб | D9: Ср. макс, руб | E9: Ср. цена, руб | F9: Диапазон
A10: Двигатель | B10: =COUNTIF('Прайс'!$B$4:$B$47,A10) -> 12 | C10: =AVERAGEIF('Прайс'!$B$4:$B$47,A10,'Прайс'!$E$4:$E$47) -> 16360 | D10: =AVERAGEIF('Прайс'!$B$4:$B$47,A10,'Прайс'!$F$4:$F$47) -> 16360 | E10: =ROUND((C10+D10)/2,0) -> 16360 | F10: =D10-C10 -> 0
A11: Трансмиссия и привод | B11: =COUNTIF('Прайс'!$B$4:$B$47,A11) -> 4 | C11: =AVERAGEIF('Прайс'!$B$4:$B$47,A11,'Прайс'!$E$4:$E$47) -> 26000 | D11: =AVERAGEIF('Прайс'!$B$4:$B$47,A11,'Прайс'!$F$4:$F$47) -> 26000 | E11: =ROUND((C11+D11)/2,0) -> 26000 | F11: =D11-C11 -> 0
A12: Подвеска и рулевое | B12: =COUNTIF('Прайс'!$B$4:$B$47,A12) -> 5 | C12: =AVERAGEIF('Прайс'!$B$4:$B$47,A12,'Прайс'!$E$4:$E$47) -> 8092 | D12: =AVERAGEIF('Прайс'!$B$4:$B$47,A12,'Прайс'!$F$4:$F$47) -> 21833 | E12: =ROUND((C12+D12)/2,0) -> 14963 | F12: =D12-C12 -> 13741
A13: Тормоза | B13: =COUNTIF('Прайс'!$B$4:$B$47,A13) -> 4 | C13: =AVERAGEIF('Прайс'!$B$4:$B$47,A13,'Прайс'!$E$4:$E$47) -> 0 | D13: =AVERAGEIF('Прайс'!$B$4:$B$47,A13,'Прайс'!$F$4:$F$47) -> 0 | E13: =ROUND((C13+D13)/2,0) -> 0 | F13: =D13-C13 -> 0
A14: Кузов и оптика | B14: =COUNTIF('Прайс'!$B$4:$B$47,A14) -> 9 | C14: =AVERAGEIF('Прайс'!$B$4:$B$47,A14,'Прайс'!$E$4:$E$47) -> 12708 | D14: =AVERAGEIF('Прайс'!$B$4:$B$47,A14,'Прайс'!$F$4:$F$47) -> 12708 | E14: =ROUND((C14+D14)/2,0) -> 12708 | F14: =D14-C14 -> 0
A15: Электрика | B15: =COUNTIF('Прайс'!$B$4:$B$47,A15) -> 5 | C15: =AVERAGEIF('Прайс'!$B$4:$B$47,A15,'Прайс'!$E$4:$E$47) -> 10278 | D15: =AVERAGEIF('Прайс'!$B$4:$B$47,A15,'Прайс'!$F$4:$F$47) -> 10278 | E15: =ROUND((C15+D15)/2,0) -> 10278 | F15: =D15-C15 -> 0
A16: Салон | B16: =COUNTIF('Прайс'!$B$4:$B$47,A16) -> 5 | C16: =AVERAGEIF('Прайс'!$B$4:$B$47,A16,'Прайс'!$E$4:$E$47) -> 15500 | D16: =AVERAGEIF('Прайс'!$B$4:$B$47,A16,'Прайс'!$F$4:$F$47) -> 15500 | E16: =ROUND((C16+D16)/2,0) -> 15500 | F16: =D16-C16 -> 0
A18: Как читать таблицу
A19: • Цены — диапазон реальных предложений б/у. Часть позиций скрывает цену в объявлении — «—» значит цена уточняется у разборки.
A20: • Диапазоны сильно зависят от региона, состояния и пробега донора; для 1.6 (21129) типичен катализатор в коллекторе.

Sheet Прайс
A1: БУ-запчасти Lada Vesta (седан, 2018 г., 1.6 21129)
A2: Цены — реальные публичные предложения б/у (сентябрь 2026): Авито, Дром, xbaz, festima, farpost и разборки. «Лучшая цена» = минимальная из найденных; ссылки открывают поиск детали на Avito и Дроме.
A3: № | B3: Категория | C3: Деталь | D3: Артикул / ориентир | E3: Цена мин, руб | F3: Цена макс, руб | G3: Ср. цена, руб | H3: Примечание | I3: Лучшая цена, руб | J3: Avito | K3: Дром
A4: 1 | B4: Двигатель | C4: Двигатель в сборе ВАЗ-21129 (контрактный) | D4: 21129 | E4: 60000 | F4: 60000 | G4: =ROUND((E4+F4)/2,0) -> 60000 | H4: baza.drom.ru — Lada XRAY 20101 21129 б/у 60 000 ₽, Челябинск | I4: =E4 -> 60000 | J4: Avito | K4: Дром
A5: 2 | B5: Двигатель | C5: Блок цилиндров | D5: 21129 | E5: — | F5: — | G5: — | H5: Авито — новый в сборе 47 800 ₽; бу-блок редок | I5: — | J5: Avito | K5: Дром
A6: 3 | B6: Двигатель | C6: ГБЦ в сборе | D6: 21129100300700 | E6: — | F6: — | G6: — | H6: Авито — б/у и новая есть, цена не раскрыта, по запросу разборок | I6: — | J6: Avito | K6: Дром
A7: 4 | B7: Двигатель | C7: Генератор 120А (контракт) | D7: TG12C209 | E7: 10000 | F7: 10000 | G7: =ROUND((E7+F7)/2,0) -> 10000 | H7: xbaz.ru (Краснодар) — 10 000 ₽ | I7: =E7 -> 10000 | J7: Avito | K7: Дром
A8: 5 | B8: Двигатель | C8: Стартер | D8: 21901-3708010-00 | E8: — | F8: — | G8: — | H8: Авито — разборы с наличием, цена не раскрыта | I8: — | J8: Avito | K8: Дром
A9: 6 | B9: Двигатель | C9: Форсунки Deka (комплект) | D9: 28346052 | E9: — | F9: — | G9: — | H9: Авито — цена за шт не раскрыта; новый комплект Delphi ~32 400 ₽ | I9: — | J9: Avito | K9: Дром
A10: 7 | B10: Двигатель | C10: Дроссельная заслонка | D10: 211271148010 | E10: 8000 | F10: 8000 | G10: =ROUND((E10+F10)/2,0) -> 8000 | H10: Авито + отчёт Drive2 — с разборки 8 000 ₽ за заводскую | I10: =E10 -> 8000 | J10: Avito | K10: Дром
A11: 8 | B11: Двигатель | C11: Датчик MAF / ДМРВ | D11: Bosch | E11: — | F11: — | G11: — | H11: бу-цены в выдержке нет — по запросу разборок | I11: — | J11: Avito | K11: Дром
A12: 9 | B12: Двигатель | C12: Термостат | E12: 2300 | F12: 2300 | G12: =ROUND((E12+F12)/2,0) -> 2300 | H12: Drive2 — отчёт владельца: 2 300 ₽ | I12: =E12 -> 2300 | J12: Avito | K12: Дром
A13: 10 | B13: Двигатель | C13: Катализатор / катколлектор | D13: 211291203008 | E13: 1500 | F13: 1500 | G13: =ROUND((E13+F13)/2,0) -> 1500 | H13: Авито — 1 500 ₽ без датчиков, пробег 38 ткм | I13: =E13 -> 1500 | J13: Avito | K13: Дром
A14: 11 | B14: Двигатель | C14: Лямбда-зонд (датчик кислорода) | D14: 226A41772R | E14: — | F14: — | G14: — | H14: Авито Пермь — за шт, цена не раскрыта; новый ~9 156 ₽ | I14: — | J14: Avito | K14: Дром
A15: 12 | B15: Двигатель | C15: Выпускной коллектор / средняя часть глушителя | D15: 8450022897 | E15: — | F15: — | G15: — | H15: Авито — б/у есть, цена не раскрыта, по запросу | I15: — | J15: Avito | K15: Дром
A16: 13 | B16: Трансмиссия и привод | C16: Вариатор Jatco JF015E | D16: JF015E/RE0F11A | E16: — | F16: — | G16: — | H16: Авито — новый оригинал 115 000 ₽; б/у редка, чаще новый/редилд | I16: — | J16: Avito | K16: Дром
A17: 14 | B17: Трансмиссия и привод | C17: МКПП контрактная (Renault JH3/JR5) | D17: JH3/JR5 | E17: 26000 | F17: 26000 | G17: =ROUND((E17+F17)/2,0) -> 26000 | H17: auto.drom.ru — контрактная оригинал 26 000 ₽ | I17: =E17 -> 26000 | J17: Avito | K17: Дром
A18: 15 | B18: Трансмиссия и привод | C18: Сцепление (комплект корзина+диск) | D18: 21810160100000 | E18: — | F18: — | G18: — | H18: бу-цены нет; новые комплекты от ~12 100 ₽ — расходник | I18: — | J18: Avito | K18: Дром
A19: 16 | B19: Трансмиссия и привод | C19: Полуоси / ШРУС | E19: — | F19: — | G19: — | H19: отдельных бу-объявлений не найдено — по запросу разборок | I19: — | J19: Avito | K19: Дром
A20: 17 | B20: Подвеска и рулевое | C20: Рычаг передней подвески | E20: 1500 | F20: 1500 | G20: =ROUND((E20+F20)/2,0) -> 1500 | H20: Авито — б/у 1 500 ₽/шт | I20: =E20 -> 1500 | J20: Avito | K20: Дром
A21: 18 | B21: Подвеска и рулевое | C21: Амортизаторы / стойки перед-зад | E21: — | F21: — | G21: — | H21: Авито — оригин. с 20 ткм, цена не раскрыта; новый СААЗ от ~4 400 ₽ | I21: — | J21: Avito | K21: Дром
A22: 19 | B22: Подвеска и рулевое | C22: Пружины | E22: — | F22: — | G22: — | H22: Авито Саратовская обл. — б/у есть, сумма не раскрыта | I22: — | J22: Avito | K22: Дром
A23: 20 | B23: Подвеска и рулевое | C23: Рулевая колонка + ЭУР (в сборе) | D23: 8450006840 | E23: 15000 | F23: 15000 | G23: =ROUND((E23+F23)/2,0) -> 15000 | H23: festima.ru — 15 000 ₽; рейка-ребилд с гарантией на Авито | I23: =E23 -> 15000 | J23: Avito | K23: Дром
A24: 21 | B24: Подвеска и рулевое | C24: ЭУР (электроусилитель, отдельно) | D24: 8450006840 | E24: 7777 | F24: 49000 | G24: =ROUND((E24+F24)/2,0) -> 28389 | H24: farpost Ростов 7 777 ₽; baza.drom Новосибирск 49 000 ₽ — разброс рынка | I24: =E24 -> 7777 | J24: Avito | K24: Дром
A25: 22 | B25: Тормоза | C25: Суппорт передний/задний | E25: — | F25: — | G25: — | H25: Авито Москва — сняты на 60 ткм, цена не раскрыта, по запросу | I25: — | J25: Avito | K25: Дром
A26: 23 | B26: Тормоза | C26: Тормозные диски / барабаны | E26: — | F26: — | G26: — | H26: бу-рынок слабый — обычно новые, по запросу разборок | I26: — | J26: Avito | K26: Дром
A27: 24 | B27: Тормоза | C27: Вакуумный усилитель + ГТЦ | E27: — | F27: — | G27: — | H27: Авито Чемодановка — б/у есть, цена не раскрыта | I27: — | J27: Avito | K27: Дром
A28: 25 | B28: Тормоза | C28: Блок ABS | E28: — | F28: — | G28: — | H28: покупка с разборки обсуждается на форумах, цена по запросу | I28: — | J28: Avito | K28: Дром
A29: 26 | B29: Кузов и оптика | C29: Капот (оригинал) | D29: 8450039378 | E29: 10000 | F29: 10000 | G29: =ROUND((E29+F29)/2,0) -> 10000 | H29: Авито, Москва — б/у оригинал 10 000 ₽ | I29: =E29 -> 10000 | J29: Avito | K29: Дром
A30: 27 | B30: Кузов и оптика | C30: Фара передняя (NG) | D30: 8450006953 | E30: 14736 | F30: 14736 | G30: =ROUND((E30+F30)/2,0) -> 14736 | H30: Авито — фара NG 14 736 ₽ | I30: =E30 -> 14736 | J30: Avito | K30: Дром
A31: 28 | B31: Кузов и оптика | C31: Задний фонарь наружный | D31: 8450006963 | E31: 8297 | F31: 8297 | G31: =ROUND((E31+F31)/2,0) -> 8297 | H31: bi-bi.ru — новый/оригинал 8 297 ₽; бу по запросу | I31: =E31 -> 8297 | J31: Avito | K31: Дром
A32: 29 | B32: Кузов и оптика | C32: Крыло переднее | D32: 8450039386 | E32: — | F32: — | G32: — | H32: Авито — б/у оригинал, цена не раскрыта; новое от 7 580 ₽ | I32: — | J32: Avito | K32: Дром
A33: 30 | B33: Кузов и оптика | C33: Бампер передний/задний | E33: — | F33: — | G33: — | H33: Авито — б/у Cross есть, цены не раскрыты, по запросу | I33: — | J33: Avito | K33: Дром
A34: 31 | B34: Кузов и оптика | C34: Дверь передняя | E34: — | F34: — | G34: — | H34: Авито — б/у оригинал, цена не раскрыта, по запросу | I34: — | J34: Avito | K34: Дром
A35: 32 | B35: Кузов и оптика | C35: Лобовое стекло | E35: 17800 | F35: 17800 | G35: =ROUND((E35+F35)/2,0) -> 17800 | H35: Авито, Уфа — новое с полным обогревом 17 800 ₽; истинного бу мало | I35: =E35 -> 17800 | J35: Avito | K35: Дром
A36: 33 | B36: Кузов и оптика | C36: Решётка радиатора | E36: — | F36: — | G36: — | H36: Авито — NG/хром есть, цены не раскрыты; новая от ~2 100 ₽ | I36: — | J36: Avito | K36: Дром
A37: 34 | B37: Кузов и оптика | C37: Крышка багажника | D37: 8450013788 | E37: — | F37: — | G37: — | H37: Авито, Тольятти — SW б/у, цена не раскрыта; задняя часть кузова ~25 000 ₽ | I37: — | J37: Avito | K37: Дром
A38: 35 | B38: Электрика | C38: ЭБУ (мозги) | D38: 8450030592 | E38: — | F38: — | G38: — | H38: Авито — б/у рабочий с гарантией, цена не раскрыта | I38: — | J38: Avito | K38: Дром
A39: 36 | B39: Электрика | C39: Панель приборов (комбинация) | D39: 8450007022 | E39: 5555 | F39: 5555 | G39: =ROUND((E39+F39)/2,0) -> 5555 | H39: Авито — комбинация от 5 555 ₽/шт б/у | I39: =E39 -> 5555 | J39: Avito | K39: Дром
A40: 37 | B40: Электрика | C40: Мультимедиа ММС (магнитола) | D40: 8450007950 | E40: 15000 | F40: 15000 | G40: =ROUND((E40+F40)/2,0) -> 15000 | H40: carbox63.ru — оригинал 15 000 ₽; бу на Авито без цены | I40: =E40 -> 15000 | J40: Avito | K40: Дром
...

Sheet Источники
A1: Источники и площадки поиска
A2: Цены собраны из публичных объявлений и каталогов 2026 г.; площадки, где проверялся каждый раздел.
A3: Площадка | B3: Что искать | C3: Тип | D3: Примечание
A4: Авито (avito.ru) | B4: Любые бу-запчасти Lada Vesta | C4: Доска объявлений | D4: Самый живой бу-рынок; часть цен скрыта в объявлениях
A5: Дром / База Дром (baza.drom.ru) | B5: Двигатель 21129, ЭУР, МКПП | C5: База объявлений | D5: Контрактные снятые узлы, вся Россия
A6: X-Baz (xbaz.ru) | B6: Генератор, по модели | C6: Агрегатор разборок | D6: Показывает конкретные суммы от разных разборок
A7: Festima (festima.ru) | B7: Рулевая колонка, ЭУР | C7: Агрегатор б/у | D7: Цены видны в карточке
A8: FarPost (farpost.ru) | B8: ЭУР, электроника | C8: Агрегатор б/у | D8: Региональные цены, часто ниже московских
A9: Drive2 (drive2.ru) | B9: Термостат, дроссель, цены запчастей | C9: Бортжурналы владельцев | D9: Отчёты с реальными ценами покупки
A10: bi-bi.ru / carbox63.ru | B10: Фонарь, ММС | C10: Магазины | D10: Ориентир по новым/оригинальным
